[2024-10-28 13:40:12,294] 1038 httpx - INFO - HTTP Request: POST https://api.openai.com/v1/chat/completions "HTTP/1.1 200 OK"
[2024-10-28 13:40:13,376] 1038 httpx - INFO - HTTP Request: POST https://api.openai.com/v1/chat/completions "HTTP/1.1 200 OK"
[2024-10-30 10:21:25,883] 1758 asyncio - ERROR - Exception in callback _HandlerDelegate.execute.<locals>.<lambda>(<Task cancell...\web.py:1746>>) at D:\Documents\Senthil\mcqg\env\lib\site-packages\tornado\web.py:2438
handle: <Handle _HandlerDelegate.execute.<locals>.<lambda>(<Task cancell...\web.py:1746>>) at D:\Documents\Senthil\mcqg\env\lib\site-packages\tornado\web.py:2438>
Traceback (most recent call last):
  File "D:\Documents\Senthil\mcqg\env\lib\site-packages\tornado\web.py", line 1746, in _execute
    async def _execute(
asyncio.exceptions.CancelledError

During handling of the above exception, another exception occurred:

Traceback (most recent call last):
  File "D:\Documents\Senthil\mcqg\env\lib\asyncio\events.py", line 80, in _run
    self._context.run(self._callback, *self._args)
  File "D:\Documents\Senthil\mcqg\env\lib\site-packages\tornado\web.py", line 2438, in <lambda>
    fut.add_done_callback(lambda f: f.result())
asyncio.exceptions.CancelledError
[2024-10-30 10:21:26,175] 1758 asyncio - ERROR - Exception in callback _HandlerDelegate.execute.<locals>.<lambda>(<Task cancell...\web.py:1746>>) at D:\Documents\Senthil\mcqg\env\lib\site-packages\tornado\web.py:2438
handle: <Handle _HandlerDelegate.execute.<locals>.<lambda>(<Task cancell...\web.py:1746>>) at D:\Documents\Senthil\mcqg\env\lib\site-packages\tornado\web.py:2438>
Traceback (most recent call last):
  File "D:\Documents\Senthil\mcqg\env\lib\site-packages\tornado\web.py", line 1746, in _execute
    async def _execute(
asyncio.exceptions.CancelledError

During handling of the above exception, another exception occurred:

Traceback (most recent call last):
  File "D:\Documents\Senthil\mcqg\env\lib\asyncio\events.py", line 80, in _run
    self._context.run(self._callback, *self._args)
  File "D:\Documents\Senthil\mcqg\env\lib\site-packages\tornado\web.py", line 2438, in <lambda>
    fut.add_done_callback(lambda f: f.result())
asyncio.exceptions.CancelledError
[2024-10-30 10:21:26,177] 1758 asyncio - ERROR - Exception in callback _HandlerDelegate.execute.<locals>.<lambda>(<Task cancell...\web.py:1746>>) at D:\Documents\Senthil\mcqg\env\lib\site-packages\tornado\web.py:2438
handle: <Handle _HandlerDelegate.execute.<locals>.<lambda>(<Task cancell...\web.py:1746>>) at D:\Documents\Senthil\mcqg\env\lib\site-packages\tornado\web.py:2438>
Traceback (most recent call last):
  File "D:\Documents\Senthil\mcqg\env\lib\site-packages\tornado\web.py", line 1746, in _execute
    async def _execute(
asyncio.exceptions.CancelledError

During handling of the above exception, another exception occurred:

Traceback (most recent call last):
  File "D:\Documents\Senthil\mcqg\env\lib\asyncio\events.py", line 80, in _run
    self._context.run(self._callback, *self._args)
  File "D:\Documents\Senthil\mcqg\env\lib\site-packages\tornado\web.py", line 2438, in <lambda>
    fut.add_done_callback(lambda f: f.result())
asyncio.exceptions.CancelledError
